Microsoft Windows [Version 10.0.19042.985]
(c) Microsoft Corporation. All rights reserved.

C:\Users\academy\Desktop\pythonstack>cd my_environments

C:\Users\academy\Desktop\pythonstack\my_environments>call djangoPy3Env\Scripts\activate

(djangoPy3Env) C:\Users\academy\Desktop\pythonstack\my_environments>cd ..

(djangoPy3Env) C:\Users\academy\Desktop\pythonstack>cd django

(djangoPy3Env) C:\Users\academy\Desktop\pythonstack\django>cd book_author_shell

(djangoPy3Env) C:\Users\academy\Desktop\pythonstack\django\book_author_shell>code .

(djangoPy3Env) C:\Users\academy\Desktop\pythonstack\django\book_author_shell>python manage.py runserver
Watching for file changes with StatReloader
Exception in thread django-main-thread:
Traceback (most recent call last):
  File "C:\Program Files\WindowsApps\PythonSoftwareFoundation.Python.3.9_3.9.1520.0_x64__qbz5n2kfra8p0\lib\threading.py", line 954, in _bootstrap_inner
    self.run()
  File "C:\Program Files\WindowsApps\PythonSoftwareFoundation.Python.3.9_3.9.1520.0_x64__qbz5n2kfra8p0\lib\threading.py", line 892, in run
    self._target(*self._args, **self._kwargs)
  File "C:\Users\academy\Desktop\pythonstack\my_environments\djangoPy3Env\lib\site-packages\django\utils\autoreload.py", line 54, in wrapper
    fn(*args, **kwargs)
  File "C:\Users\academy\Desktop\pythonstack\my_environments\djangoPy3Env\lib\site-packages\django\core\management\commands\runserver.py", line 109, in inner_run
    autoreload.raise_last_exception()
  File "C:\Users\academy\Desktop\pythonstack\my_environments\djangoPy3Env\lib\site-packages\django\utils\autoreload.py", line 77, in raise_last_exception
    raise _exception[1]
  File "C:\Users\academy\Desktop\pythonstack\my_environments\djangoPy3Env\lib\site-packages\django\core\management\__init__.py", line 337, in execute
    autoreload.check_errors(django.setup)()
  File "C:\Users\academy\Desktop\pythonstack\my_environments\djangoPy3Env\lib\site-packages\django\utils\autoreload.py", line 54, in wrapper
    fn(*args, **kwargs)
  File "C:\Users\academy\Desktop\pythonstack\my_environments\djangoPy3Env\lib\site-packages\django\__init__.py", line 24, in setup
    apps.populate(settings.INSTALLED_APPS)
  File "C:\Users\academy\Desktop\pythonstack\my_environments\djangoPy3Env\lib\site-packages\django\apps\registry.py", line 114, in populate
    app_config.import_models()
  File "C:\Users\academy\Desktop\pythonstack\my_environments\djangoPy3Env\lib\site-packages\django\apps\config.py", line 211, in import_models
    self.models_module = import_module(models_module_name)
  File "C:\Program Files\WindowsApps\PythonSoftwareFoundation.Python.3.9_3.9.1520.0_x64__qbz5n2kfra8p0\lib\importlib\__init__.py", line 127, in import_module
    return _bootstrap._gcd_import(name[level:], package, level)
  File "<frozen importlib._bootstrap>", line 1030, in _gcd_import
  File "<frozen importlib._bootstrap>", line 1007, in _find_and_load
  File "<frozen importlib._bootstrap>", line 986, in _find_and_load_unlocked
  File "<frozen importlib._bootstrap>", line 680, in _load_unlocked
  File "<frozen importlib._bootstrap_external>", line 855, in exec_module
  File "<frozen importlib._bootstrap>", line 228, in _call_with_frames_removed
  File "C:\Users\academy\Desktop\pythonstack\django\book_author_shell\book_author\models.py", line 8, in <module>
    class Author(models.Model):
  File "C:\Users\academy\Desktop\pythonstack\django\book_author_shell\book_author\models.py", line 11, in Author
    clients = models.ManyToManyField(User,related_name = "authors")
NameError: name 'User' is not defined

(djangoPy3Env) C:\Users\academy\Desktop\pythonstack\django\book_author_shell>python manage.py runserver
Watching for file changes with StatReloader
Performing system checks...

System check identified no issues (0 silenced).
May 24, 2021 - 16:00:12
Django version 2.2.4, using settings 'book_author_shell.settings'
Starting development server at http://127.0.0.1:8000/
Quit the server with CTRL-BREAK.

(djangoPy3Env) C:\Users\academy\Desktop\pythonstack\django\book_author_shell>python manage.py runserver
Watching for file changes with StatReloader
Exception in thread django-main-thread:
Traceback (most recent call last):
  File "C:\Program Files\WindowsApps\PythonSoftwareFoundation.Python.3.9_3.9.1520.0_x64__qbz5n2kfra8p0\lib\threading.py", line 954, in _bootstrap_inner
    self.run()
  File "C:\Program Files\WindowsApps\PythonSoftwareFoundation.Python.3.9_3.9.1520.0_x64__qbz5n2kfra8p0\lib\threading.py", line 892, in run
    self._target(*self._args, **self._kwargs)
  File "C:\Users\academy\Desktop\pythonstack\my_environments\djangoPy3Env\lib\site-packages\django\utils\autoreload.py", line 54, in wrapper
    fn(*args, **kwargs)
  File "C:\Users\academy\Desktop\pythonstack\my_environments\djangoPy3Env\lib\site-packages\django\core\management\commands\runserver.py", line 109, in inner_run
    autoreload.raise_last_exception()
  File "C:\Users\academy\Desktop\pythonstack\my_environments\djangoPy3Env\lib\site-packages\django\utils\autoreload.py", line 77, in raise_last_exception
    raise _exception[1]
  File "C:\Users\academy\Desktop\pythonstack\my_environments\djangoPy3Env\lib\site-packages\django\core\management\__init__.py", line 337, in execute
    autoreload.check_errors(django.setup)()
  File "C:\Users\academy\Desktop\pythonstack\my_environments\djangoPy3Env\lib\site-packages\django\utils\autoreload.py", line 54, in wrapper
    fn(*args, **kwargs)
  File "C:\Users\academy\Desktop\pythonstack\my_environments\djangoPy3Env\lib\site-packages\django\__init__.py", line 24, in setup
    apps.populate(settings.INSTALLED_APPS)
  File "C:\Users\academy\Desktop\pythonstack\my_environments\djangoPy3Env\lib\site-packages\django\apps\registry.py", line 114, in populate
    app_config.import_models()
  File "C:\Users\academy\Desktop\pythonstack\my_environments\djangoPy3Env\lib\site-packages\django\apps\config.py", line 211, in import_models
    self.models_module = import_module(models_module_name)
  File "C:\Program Files\WindowsApps\PythonSoftwareFoundation.Python.3.9_3.9.1520.0_x64__qbz5n2kfra8p0\lib\importlib\__init__.py", line 127, in import_module
    return _bootstrap._gcd_import(name[level:], package, level)
  File "<frozen importlib._bootstrap>", line 1030, in _gcd_import
  File "<frozen importlib._bootstrap>", line 1007, in _find_and_load
  File "<frozen importlib._bootstrap>", line 986, in _find_and_load_unlocked
  File "<frozen importlib._bootstrap>", line 680, in _load_unlocked
  File "<frozen importlib._bootstrap_external>", line 855, in exec_module
  File "<frozen importlib._bootstrap>", line 228, in _call_with_frames_removed
  File "C:\Users\academy\Desktop\pythonstack\django\book_author_shell\book_author\models.py", line 2, in <module>
    class Book(models.Model):
  File "C:\Users\academy\Desktop\pythonstack\django\book_author_shell\book_author\models.py", line 4, in Book
    desc = models.TextFeild()
AttributeError: module 'django.db.models' has no attribute 'TextFeild'
C:\Users\academy\Desktop\pythonstack\django\book_author_shell\book_author\models.py changed, reloading.
Watching for file changes with StatReloader
Performing system checks...

System check identified no issues (0 silenced).
May 24, 2021 - 16:01:18
Django version 2.2.4, using settings 'book_author_shell.settings'
Starting development server at http://127.0.0.1:8000/
Quit the server with CTRL-BREAK.

(djangoPy3Env) C:\Users\academy\Desktop\pythonstack\django\book_author_shell>python manage.py makemigrations
Migrations for 'book_author':
  book_author\migrations\0001_initial.py
    - Create model Book
    - Create model Author

(djangoPy3Env) C:\Users\academy\Desktop\pythonstack\django\book_author_shell>python manage.py migrates
Unknown command: 'migrates'. Did you mean migrate?
Type 'manage.py help' for usage.

(djangoPy3Env) C:\Users\academy\Desktop\pythonstack\django\book_author_shell>python manage.py migrate
Operations to perform:
  Apply all migrations: admin, auth, book_author, contenttypes, sessions
Running migrations:
  Applying book_author.0001_initial... OK

(djangoPy3Env) C:\Users\academy\Desktop\pythonstack\django\book_author_shell>python manage.py shell
Python 3.9.5 (tags/v3.9.5:0a7dcbd, May  3 2021, 17:27:52) [MSC v.1928 64 bit (AMD64)] on win32
Type "help", "copyright", "credits" or "license" for more information.
(InteractiveConsole)
>>> from book_author.models import*
>>> csharp = create.objects.models(title = "Csharp")
Traceback (most recent call last):
  File "<console>", line 1, in <module>
NameError: name 'create' is not defined
>>> csharp = objects.models.create(title = "Csharp")
Traceback (most recent call last):
  File "<console>", line 1, in <module>
NameError: name 'objects' is not defined
>>> csharp = Book.create(title = "Csharp")
Traceback (most recent call last):
  File "<console>", line 1, in <module>
AttributeError: type object 'Book' has no attribute 'create'
>>> csharp = Book.objects.create(title = "Csharp")
>>> java = Book.objects.create(title = "Java")
>>> python = Book.objects.create(title = "Python")
>>> ruby = Book.objects.create(title = "Ruby")
>>> php = Book.objects.create(title = "Php")
>>> jane = Author.objects.create(first_name = "Jane",Last_name = "Austen")
Traceback (most recent call last):
  File "<console>", line 1, in <module>
  File "C:\Users\academy\Desktop\pythonstack\my_environments\djangoPy3Env\lib\site-packages\django\db\models\manager.py", line 82, in manager_method
    return getattr(self.get_queryset(), name)(*args, **kwargs)
  File "C:\Users\academy\Desktop\pythonstack\my_environments\djangoPy3Env\lib\site-packages\django\db\models\query.py", line 420, in create
    obj = self.model(**kwargs)
  File "C:\Users\academy\Desktop\pythonstack\my_environments\djangoPy3Env\lib\site-packages\django\db\models\base.py", line 501, in __init__
    raise TypeError("%s() got an unexpected keyword argument '%s'" % (cls.__name__, kwarg))
TypeError: Author() got an unexpected keyword argument 'Last_name'
>>> jane = Author.objects.create(first_name = "Jane",last_name = "Austen")
>>> emily = Author.objects.create(first_name = "Emily",last_name = "Dickinson")
>>> fyodor = Author.objects.create(first_name = "Fyodor",last_name = "Dostoevsky")
>>> william = Author.objects.create(first_name = "William",Last_name = " Shakespeare")
Traceback (most recent call last):
  File "<console>", line 1, in <module>
  File "C:\Users\academy\Desktop\pythonstack\my_environments\djangoPy3Env\lib\site-packages\django\db\models\manager.py", line 82, in manager_method
    return getattr(self.get_queryset(), name)(*args, **kwargs)
  File "C:\Users\academy\Desktop\pythonstack\my_environments\djangoPy3Env\lib\site-packages\django\db\models\query.py", line 420, in create
    obj = self.model(**kwargs)
  File "C:\Users\academy\Desktop\pythonstack\my_environments\djangoPy3Env\lib\site-packages\django\db\models\base.py", line 501, in __init__
    raise TypeError("%s() got an unexpected keyword argument '%s'" % (cls.__name__, kwarg))
TypeError: Author() got an unexpected keyword argument 'Last_name'
>>> william = Author.objects.create(first_name = "William",last_name = " Shakespeare")
>>> lau = Author.objects.create(first_name = "Lau",last_name = " Tzu")
>>> exit()

(djangoPy3Env) C:\Users\academy\Desktop\pythonstack\django\book_author_shell>python manage.py makemigrations
Traceback (most recent call last):
  File "C:\Users\academy\Desktop\pythonstack\django\book_author_shell\manage.py", line 21, in <module>
    main()
  File "C:\Users\academy\Desktop\pythonstack\django\book_author_shell\manage.py", line 17, in main
    execute_from_command_line(sys.argv)
  File "C:\Users\academy\Desktop\pythonstack\my_environments\djangoPy3Env\lib\site-packages\django\core\management\__init__.py", line 381, in execute_from_command_line
    utility.execute()
  File "C:\Users\academy\Desktop\pythonstack\my_environments\djangoPy3Env\lib\site-packages\django\core\management\__init__.py", line 357, in execute
    django.setup()
  File "C:\Users\academy\Desktop\pythonstack\my_environments\djangoPy3Env\lib\site-packages\django\__init__.py", line 24, in setup
    apps.populate(settings.INSTALLED_APPS)
  File "C:\Users\academy\Desktop\pythonstack\my_environments\djangoPy3Env\lib\site-packages\django\apps\registry.py", line 114, in populate
    app_config.import_models()
  File "C:\Users\academy\Desktop\pythonstack\my_environments\djangoPy3Env\lib\site-packages\django\apps\config.py", line 211, in import_models
    self.models_module = import_module(models_module_name)
  File "C:\Program Files\WindowsApps\PythonSoftwareFoundation.Python.3.9_3.9.1520.0_x64__qbz5n2kfra8p0\lib\importlib\__init__.py", line 127, in import_module
    return _bootstrap._gcd_import(name[level:], package, level)
  File "<frozen importlib._bootstrap>", line 1030, in _gcd_import
  File "<frozen importlib._bootstrap>", line 1007, in _find_and_load
  File "<frozen importlib._bootstrap>", line 986, in _find_and_load_unlocked
  File "<frozen importlib._bootstrap>", line 680, in _load_unlocked
  File "<frozen importlib._bootstrap_external>", line 855, in exec_module
  File "<frozen importlib._bootstrap>", line 228, in _call_with_frames_removed
  File "C:\Users\academy\Desktop\pythonstack\django\book_author_shell\book_author\models.py", line 8, in <module>
    class Author(models.Model):
  File "C:\Users\academy\Desktop\pythonstack\django\book_author_shell\book_author\models.py", line 14, in Author
    notes = models.CharFeild(max_length=200)
AttributeError: module 'django.db.models' has no attribute 'CharFeild'

(djangoPy3Env) C:\Users\academy\Desktop\pythonstack\django\book_author_shell>python manage.py makemigrations
Traceback (most recent call last):
  File "C:\Users\academy\Desktop\pythonstack\django\book_author_shell\manage.py", line 21, in <module>
    main()
  File "C:\Users\academy\Desktop\pythonstack\django\book_author_shell\manage.py", line 17, in main
    execute_from_command_line(sys.argv)
  File "C:\Users\academy\Desktop\pythonstack\my_environments\djangoPy3Env\lib\site-packages\django\core\management\__init__.py", line 381, in execute_from_command_line
    utility.execute()
  File "C:\Users\academy\Desktop\pythonstack\my_environments\djangoPy3Env\lib\site-packages\django\core\management\__init__.py", line 357, in execute
    django.setup()
  File "C:\Users\academy\Desktop\pythonstack\my_environments\djangoPy3Env\lib\site-packages\django\__init__.py", line 24, in setup
    apps.populate(settings.INSTALLED_APPS)
  File "C:\Users\academy\Desktop\pythonstack\my_environments\djangoPy3Env\lib\site-packages\django\apps\registry.py", line 114, in populate
    app_config.import_models()
  File "C:\Users\academy\Desktop\pythonstack\my_environments\djangoPy3Env\lib\site-packages\django\apps\config.py", line 211, in import_models
    self.models_module = import_module(models_module_name)
  File "C:\Program Files\WindowsApps\PythonSoftwareFoundation.Python.3.9_3.9.1520.0_x64__qbz5n2kfra8p0\lib\importlib\__init__.py", line 127, in import_module
    return _bootstrap._gcd_import(name[level:], package, level)
  File "<frozen importlib._bootstrap>", line 1030, in _gcd_import
  File "<frozen importlib._bootstrap>", line 1007, in _find_and_load
  File "<frozen importlib._bootstrap>", line 986, in _find_and_load_unlocked
  File "<frozen importlib._bootstrap>", line 680, in _load_unlocked
  File "<frozen importlib._bootstrap_external>", line 851, in exec_module
  File "<frozen importlib._bootstrap_external>", line 988, in get_code
  File "<frozen importlib._bootstrap_external>", line 918, in source_to_code
  File "<frozen importlib._bootstrap>", line 228, in _call_with_frames_removed
  File "C:\Users\academy\Desktop\pythonstack\django\book_author_shell\book_author\models.py", line 4
    desc = models.TextField()
IndentationError: unexpected indent

(djangoPy3Env) C:\Users\academy\Desktop\pythonstack\django\book_author_shell>python manage.py makemigrations
You are trying to add a non-nullable field 'notes' to author without a default; we can't do that (the database needs something to populate existing rows).
Please select a fix:
 1) Provide a one-off default now (will be set on all existing rows with a null value for this column)
 2) Quit, and let me add a default in models.py
Select an option: 1
Please enter the default value now, as valid Python
The datetime and django.utils.timezone modules are available, so you can do e.g. timezone.now
Type 'exit' to exit this prompt
>>> exit()

(djangoPy3Env) C:\Users\academy\Desktop\pythonstack\django\book_author_shell>python manage.py makemigrations
You are trying to add a non-nullable field 'notes' to author without a default; we can't do that (the database needs something to populate existing rows).
Please select a fix:
 1) Provide a one-off default now (will be set on all existing rows with a null value for this column)
 2) Quit, and let me add a default in models.py
Select an option: exit()
Please select a valid option: 1
Please enter the default value now, as valid Python
The datetime and django.utils.timezone modules are available, so you can do e.g. timezone.now
Type 'exit' to exit this prompt
>>> exit()

(djangoPy3Env) C:\Users\academy\Desktop\pythonstack\django\book_author_shell>python manage.py runserver
Watching for file changes with StatReloader
Performing system checks...

System check identified no issues (0 silenced).
May 24, 2021 - 16:23:39
Django version 2.2.4, using settings 'book_author_shell.settings'
Starting development server at http://127.0.0.1:8000/
Quit the server with CTRL-BREAK.

(djangoPy3Env) C:\Users\academy\Desktop\pythonstack\django\book_author_shell>python manage.py makemigrations
You are trying to add a non-nullable field 'notes' to author without a default; we can't do that (the database needs something to populate existing rows).
Please select a fix:
 1) Provide a one-off default now (will be set on all existing rows with a null value for this column)
 2) Quit, and let me add a default in models.py
Select an option: 1
Please enter the default value now, as valid Python
The datetime and django.utils.timezone modules are available, so you can do e.g. timezone.now
Type 'exit' to exit this prompt
>>> exit()

(djangoPy3Env) C:\Users\academy\Desktop\pythonstack\django\book_author_shell>python manage.py makemigrations
SystemCheckError: System check identified some issues:

ERRORS:
book_author.Author.notes: (fields.E120) CharFields must define a 'max_length' attribute.

(djangoPy3Env) C:\Users\academy\Desktop\pythonstack\django\book_author_shell>python manage.py makemigrations
You are trying to add a non-nullable field 'notes' to author without a default; we can't do that (the database needs something to populate existing rows).
Please select a fix:
 1) Provide a one-off default now (will be set on all existing rows with a null value for this column)
 2) Quit, and let me add a default in models.py
Select an option: 1
Please enter the default value now, as valid Python
The datetime and django.utils.timezone modules are available, so you can do e.g. timezone.now
Type 'exit' to exit this prompt
>>> exit()

(djangoPy3Env) C:\Users\academy\Desktop\pythonstack\django\book_author_shell>python manage.py makemigrations
You are trying to add a non-nullable field 'desc' to book without a default; we can't do that (the database needs something to populate existing rows).
Please select a fix:
 1) Provide a one-off default now (will be set on all existing rows with a null value for this column)
 2) Quit, and let me add a default in models.py
Select an option: 1
Please enter the default value now, as valid Python
The datetime and django.utils.timezone modules are available, so you can do e.g. timezone.now
Type 'exit' to exit this prompt
>>> exit()

(djangoPy3Env) C:\Users\academy\Desktop\pythonstack\django\book_author_shell>python manage.py makemigrations
Migrations for 'book_author':
  book_author\migrations\0002_auto_20210524_1629.py
    - Add field notes to author
    - Add field desc to book

(djangoPy3Env) C:\Users\academy\Desktop\pythonstack\django\book_author_shell>python manage.py migrate
Operations to perform:
  Apply all migrations: admin, auth, book_author, contenttypes, sessions
Running migrations:
  Applying book_author.0002_auto_20210524_1629... OK

(djangoPy3Env) C:\Users\academy\Desktop\pythonstack\django\book_author_shell>python manage.py shell
Python 3.9.5 (tags/v3.9.5:0a7dcbd, May  3 2021, 17:27:52) [MSC v.1928 64 bit (AMD64)] on win32
Type "help", "copyright", "credits" or "license" for more information.
(InteractiveConsole)
>>> c = Book.objects.get(id=1)
Traceback (most recent call last):
  File "<console>", line 1, in <module>
NameError: name 'Book' is not defined
>>> book = Book.objects.get(id=1)
Traceback (most recent call last):
  File "<console>", line 1, in <module>
NameError: name 'Book' is not defined
>>> from book_author.models import*
>>> book = Book.objects.get(id=1)
>>> book.title = "C#"
>>> book.save()
>>>  book = Author.objects.get(id=4)
  File "<console>", line 1
    book = Author.objects.get(id=4)
IndentationError: unexpected indent
>>> book = Author.objects.get(id=4)
>>> book.last_name = "Bill"
>>> book.save()
>>> Jane.authors.add(C#)
... Jane.authors.add(Java)
  File "<console>", line 2
    Jane.authors.add(Java)
    ^
SyntaxError: invalid syntax
>>> Jane.authors.add(Java)
Traceback (most recent call last):
  File "<console>", line 1, in <module>
NameError: name 'Jane' is not defined
>>> Jane.authors.add(C#,Java)
... Emily.authors.add(C#,Java,Python)
  File "<console>", line 2
    Emily.authors.add(C#,Java,Python)
    ^
SyntaxError: invalid syntax
>>> Emily.authors.add(C#,Java,Python)
...
...
...
...
...
...
...
...
...
...
...
...
...
...
...
...
...
... \
...
...
...
... ghhdfhfhd
  File "<console>", line 23
    ghhdfhfhd
    ^
SyntaxError: invalid syntax
>>> Emily.authors.add(C#,Java,Python)
...
...
...
...
...
...
...
...
...
...
...
...
...
...
...
...
...
...
...
...
...
...
...
...
...
...
...
...
...
...
...
...
...
...
...
...
...
...
...
...
...
...
...
...
...
...
...
...
...
...
...
...
... dsfsdfggf
  File "<console>", line 54
    dsfsdfggf
    ^
SyntaxError: invalid syntax
>>> Fyodor.authors.add(C#,Java,Python,Ruby)
...
...
...
... Fyodor.authors.add(C#)
  File "<console>", line 5
    Fyodor.authors.add(C#)
    ^
SyntaxError: invalid syntax
>>> Jane.title.add(C#)
...
... Jane.title.add(C#)
  File "<console>", line 3
    Jane.title.add(C#)
    ^
SyntaxError: invalid syntax
>>> book1=Book.objects.get(id=1)
>>>     book1=Book.objects.get(id=2)
  File "<console>", line 1
    book1=Book.objects.get(id=2)
IndentationError: unexpected indent
>>>     book1=Book.objects.get(id=3)
  File "<console>", line 1
    book1=Book.objects.get(id=3)
IndentationError: unexpected indent
>>>     author2=Author.objects.get(id=2)
  File "<console>", line 1
    author2=Author.objects.get(id=2)
IndentationError: unexpected indent
>>>     book1.clients.add(author2)
  File "<console>", line 1
    book1.clients.add(author2)
IndentationError: unexpected indent
>>>     book2.clients.add(author2)
  File "<console>", line 1
    book2.clients.add(author2)
IndentationError: unexpected indent
>>>     book3.clients.add(author2)
  File "<console>", line 1
    book3.clients.add(author2)
IndentationError: unexpected indent
>>> book1=Book.objects.get(id=1)
>>> book1=Book.objects.get(id=2)
>>> book1=Book.objects.get(id=3)
>>> author2=Author.objects.get(id=2)
>>> book1.clients.add(author2)
Traceback (most recent call last):
  File "<console>", line 1, in <module>
AttributeError: 'Book' object has no attribute 'clients'
>>> book2.clients.add(author2)
Traceback (most recent call last):
  File "<console>", line 1, in <module>
NameError: name 'book2' is not defined
>>> book3.clients.add(author2)
Traceback (most recent call last):
  File "<console>", line 1, in <module>
NameError: name 'book3' is not defined
>>> book1=Book.objects.get(id=1)
>>> book2=Book.objects.get(id=2)
>>> book3=Book.objects.get(id=3)
>>> author2=Author.objects.get(id=2)
>>> book1.clients.add(author2)
Traceback (most recent call last):
  File "<console>", line 1, in <module>
AttributeError: 'Book' object has no attribute 'clients'
>>> author2.books.add(book1)
Traceback (most recent call last):
  File "<console>", line 1, in <module>
AttributeError: 'Author' object has no attribute 'books'
>>> author2.clients.add(book1)
>>> author2.clients.add(book2)
>>> author2.clients.add(book3)
>>> book1=Book.objects.get(id=1)
>>> book2=Book.objects.get(id=2)
>>> author1=Author.objects.get(id=1)
>>> author1.clients.add(book1)
>>> author1.clients.add(book2)
>>> author3.clients.add(book1)
Traceback (most recent call last):
  File "<console>", line 1, in <module>
NameError: name 'author3' is not defined
>>> book1=Book.objects.get(id=1)
>>> book2=Book.objects.get(id=2)
>>> book3=Book.objects.get(id=3)
>>> book4=Book.objects.get(id=4)
>>> author3=Author.objects.get(id=3)
>>> author3.clients.add(book1)
>>> author3.clients.add(book2)
>>> author3.clients.add(book3)
>>> author3.clients.add(book4)
>>> book1=Book.objects.get(id=1)
>>> book2=Book.objects.get(id=2)
>>> book3=Book.objects.get(id=3)
>>> book4=Book.objects.get(id=4)
>>> book5=Book.objects.get(id=5)
>>> author4=Author.objects.get(id=4)
>>> Book.objects.get(title ="Python" )
<Book: Book object (3)>
>>> c = ClassName.objects.get(title="Python")
Traceback (most recent call last):
  File "<console>", line 1, in <module>
NameError: name 'ClassName' is not defined
>>> c = Book.objects.get(title="Python")
>>> c.delete()
(3, {'book_author.Author_clients': 2, 'book_author.Book': 1})
>>> Author.objects.create(first_name = "mohammed",last_name = "hammouz")
<Author: Author object (6)>
>>>